2024-04-11 17:27:21,067 ERROR: Exception on /users [GET] [in /Users/lambo/turing/work/4mod/projects/capstone/capstone_py/stream_cycle/venv/lib/python3.12/site-packages/flask/app.py:838]
Traceback (most recent call last):
  File "/Users/lambo/turing/work/4mod/projects/capstone/capstone_py/stream_cycle/venv/lib/python3.12/site-packages/flask/app.py", line 1473, in wsgi_app
    response = self.full_dispatch_request()
               ^^^^^^^^^^^^^^^^^^^^^^^^^^^^
  File "/Users/lambo/turing/work/4mod/projects/capstone/capstone_py/stream_cycle/venv/lib/python3.12/site-packages/flask/app.py", line 882, in full_dispatch_request
    rv = self.handle_user_exception(e)
         ^^^^^^^^^^^^^^^^^^^^^^^^^^^^^
  File "/Users/lambo/turing/work/4mod/projects/capstone/capstone_py/stream_cycle/venv/lib/python3.12/site-packages/flask_cors/extension.py", line 176, in wrapped_function
    return cors_after_request(app.make_response(f(*args, **kwargs)))
                                                ^^^^^^^^^^^^^^^^^^
  File "/Users/lambo/turing/work/4mod/projects/capstone/capstone_py/stream_cycle/venv/lib/python3.12/site-packages/flask/app.py", line 880, in full_dispatch_request
    rv = self.dispatch_request()
         ^^^^^^^^^^^^^^^^^^^^^^^
  File "/Users/lambo/turing/work/4mod/projects/capstone/capstone_py/stream_cycle/venv/lib/python3.12/site-packages/flask/app.py", line 865, in dispatch_request
    return self.ensure_sync(self.view_functions[rule.endpoint])(**view_args)  # type: ignore[no-any-return]
           ^^^^^^^^^^^^^^^^^^^^^^^^^^^^^^^^^^^^^^^^^^^^^^^^^^^^^^^^^^^^^^^^^
  File "/Users/lambo/turing/work/4mod/projects/capstone/capstone_py/stream_cycle/app/routes/user_routes.py", line 35, in get_users
    users = User.query.all()
            ^^^^^^^^^^^^^^^^
  File "/Users/lambo/turing/work/4mod/projects/capstone/capstone_py/stream_cycle/venv/lib/python3.12/site-packages/sqlalchemy/orm/query.py", line 2673, in all
    return self._iter().all()  # type: ignore
           ^^^^^^^^^^^^
  File "/Users/lambo/turing/work/4mod/projects/capstone/capstone_py/stream_cycle/venv/lib/python3.12/site-packages/sqlalchemy/orm/query.py", line 2827, in _iter
    result: Union[ScalarResult[_T], Result[_T]] = self.session.execute(
                                                  ^^^^^^^^^^^^^^^^^^^^^
  File "/Users/lambo/turing/work/4mod/projects/capstone/capstone_py/stream_cycle/venv/lib/python3.12/site-packages/sqlalchemy/orm/session.py", line 2306, in execute
    return self._execute_internal(
           ^^^^^^^^^^^^^^^^^^^^^^^
  File "/Users/lambo/turing/work/4mod/projects/capstone/capstone_py/stream_cycle/venv/lib/python3.12/site-packages/sqlalchemy/orm/session.py", line 2170, in _execute_internal
    ) = compile_state_cls.orm_pre_session_exec(
        ^^^^^^^^^^^^^^^^^^^^^^^^^^^^^^^^^^^^^^^
  File "/Users/lambo/turing/work/4mod/projects/capstone/capstone_py/stream_cycle/venv/lib/python3.12/site-packages/sqlalchemy/orm/context.py", line 549, in orm_pre_session_exec
    session._autoflush()
  File "/Users/lambo/turing/work/4mod/projects/capstone/capstone_py/stream_cycle/venv/lib/python3.12/site-packages/sqlalchemy/orm/session.py", line 2994, in _autoflush
    self.flush()
  File "/Users/lambo/turing/work/4mod/projects/capstone/capstone_py/stream_cycle/venv/lib/python3.12/site-packages/sqlalchemy/orm/session.py", line 4296, in flush
    self._flush(objects)
  File "/Users/lambo/turing/work/4mod/projects/capstone/capstone_py/stream_cycle/venv/lib/python3.12/site-packages/sqlalchemy/orm/session.py", line 4388, in _flush
    flush_context.transaction = transaction = self._autobegin_t()._begin()
                                              ^^^^^^^^^^^^^^^^^^^^^^^^^^^^
  File "<string>", line 2, in _begin
  File "/Users/lambo/turing/work/4mod/projects/capstone/capstone_py/stream_cycle/venv/lib/python3.12/site-packages/sqlalchemy/orm/state_changes.py", line 103, in _go
    self._raise_for_prerequisite_state(fn.__name__, current_state)
  File "/Users/lambo/turing/work/4mod/projects/capstone/capstone_py/stream_cycle/venv/lib/python3.12/site-packages/sqlalchemy/orm/session.py", line 928, in _raise_for_prerequisite_state
    raise sa_exc.PendingRollbackError(
sqlalchemy.exc.PendingRollbackError: This Session's transaction has been rolled back due to a previous exception during flush. To begin a new transaction with this Session, first issue Session.rollback(). Original exception was: (psycopg2.errors.UniqueViolation) duplicate key value violates unique constraint "users_email_key"
DETAIL:  Key (email)=(test@example.com) already exists.

[SQL: INSERT INTO users (email, first_name, last_name, created_at, updated_at) VALUES (%(email)s, %(first_name)s, %(last_name)s, %(created_at)s, %(updated_at)s) RETURNING users.id]
[parameters: {'email': 'test@example.com', 'first_name': 'Test', 'last_name': 'User', 'created_at': datetime.datetime(2024, 4, 11, 22, 27, 20, 823944, tzinfo=datetime.timezone.utc), 'updated_at': datetime.datetime(2024, 4, 11, 22, 27, 20, 823948, tzinfo=datetime.timezone.utc)}]
(Background on this error at: https://sqlalche.me/e/20/gkpj) (Background on this error at: https://sqlalche.me/e/20/7s2a)
2024-04-11 17:29:05,299 INFO: Your application startup [in /Users/lambo/turing/work/4mod/projects/capstone/capstone_py/stream_cycle/app/__init__.py:31]
2024-04-11 18:16:05,260 INFO: Your application startup [in /Users/lambo/turing/work/4mod/projects/capstone/capstone_py/stream_cycle/app/__init__.py:31]
