2024-04-11 18:16:23,440 ERROR: Exception on /users/10 [GET] [in /Users/lambo/turing/work/4mod/projects/capstone/capstone_py/stream_cycle/venv/lib/python3.12/site-packages/flask/app.py:838]
Traceback (most recent call last):
  File "/Users/lambo/turing/work/4mod/projects/capstone/capstone_py/stream_cycle/venv/lib/python3.12/site-packages/sqlalchemy/engine/base.py", line 1971, in _exec_single_context
    self.dialect.do_execute(
  File "/Users/lambo/turing/work/4mod/projects/capstone/capstone_py/stream_cycle/venv/lib/python3.12/site-packages/sqlalchemy/engine/default.py", line 919, in do_execute
    cursor.execute(statement, parameters)
psycopg2.errors.UndefinedTable: relation "users" does not exist
LINE 2: FROM users 
             ^


The above exception was the direct cause of the following exception:

Traceback (most recent call last):
  File "/Users/lambo/turing/work/4mod/projects/capstone/capstone_py/stream_cycle/venv/lib/python3.12/site-packages/flask/app.py", line 1473, in wsgi_app
    response = self.full_dispatch_request()
               ^^^^^^^^^^^^^^^^^^^^^^^^^^^^
  File "/Users/lambo/turing/work/4mod/projects/capstone/capstone_py/stream_cycle/venv/lib/python3.12/site-packages/flask/app.py", line 882, in full_dispatch_request
    rv = self.handle_user_exception(e)
         ^^^^^^^^^^^^^^^^^^^^^^^^^^^^^
  File "/Users/lambo/turing/work/4mod/projects/capstone/capstone_py/stream_cycle/venv/lib/python3.12/site-packages/flask_cors/extension.py", line 176, in wrapped_function
    return cors_after_request(app.make_response(f(*args, **kwargs)))
                                                ^^^^^^^^^^^^^^^^^^
  File "/Users/lambo/turing/work/4mod/projects/capstone/capstone_py/stream_cycle/venv/lib/python3.12/site-packages/flask/app.py", line 880, in full_dispatch_request
    rv = self.dispatch_request()
         ^^^^^^^^^^^^^^^^^^^^^^^
  File "/Users/lambo/turing/work/4mod/projects/capstone/capstone_py/stream_cycle/venv/lib/python3.12/site-packages/flask/app.py", line 865, in dispatch_request
    return self.ensure_sync(self.view_functions[rule.endpoint])(**view_args)  # type: ignore[no-any-return]
           ^^^^^^^^^^^^^^^^^^^^^^^^^^^^^^^^^^^^^^^^^^^^^^^^^^^^^^^^^^^^^^^^^
  File "/Users/lambo/turing/work/4mod/projects/capstone/capstone_py/stream_cycle/app/routes/user_routes.py", line 25, in get_user
    user = User.query.get_or_404(user_id)
           ^^^^^^^^^^^^^^^^^^^^^^^^^^^^^^
  File "/Users/lambo/turing/work/4mod/projects/capstone/capstone_py/stream_cycle/venv/lib/python3.12/site-packages/flask_sqlalchemy/query.py", line 30, in get_or_404
    rv = self.get(ident)
         ^^^^^^^^^^^^^^^
  File "<string>", line 2, in get
  File "/Users/lambo/turing/work/4mod/projects/capstone/capstone_py/stream_cycle/venv/lib/python3.12/site-packages/sqlalchemy/util/deprecations.py", line 386, in warned
    return fn(*args, **kwargs)  # type: ignore[no-any-return]
           ^^^^^^^^^^^^^^^^^^^
  File "/Users/lambo/turing/work/4mod/projects/capstone/capstone_py/stream_cycle/venv/lib/python3.12/site-packages/sqlalchemy/orm/query.py", line 1127, in get
    return self._get_impl(ident, loading.load_on_pk_identity)
           ^^^^^^^^^^^^^^^^^^^^^^^^^^^^^^^^^^^^^^^^^^^^^^^^^^
  File "/Users/lambo/turing/work/4mod/projects/capstone/capstone_py/stream_cycle/venv/lib/python3.12/site-packages/sqlalchemy/orm/query.py", line 1136, in _get_impl
    return self.session._get_impl(
           ^^^^^^^^^^^^^^^^^^^^^^^
  File "/Users/lambo/turing/work/4mod/projects/capstone/capstone_py/stream_cycle/venv/lib/python3.12/site-packages/sqlalchemy/orm/session.py", line 3817, in _get_impl
    return db_load_fn(
           ^^^^^^^^^^^
  File "/Users/lambo/turing/work/4mod/projects/capstone/capstone_py/stream_cycle/venv/lib/python3.12/site-packages/sqlalchemy/orm/loading.py", line 694, in load_on_pk_identity
    session.execute(
  File "/Users/lambo/turing/work/4mod/projects/capstone/capstone_py/stream_cycle/venv/lib/python3.12/site-packages/sqlalchemy/orm/session.py", line 2306, in execute
    return self._execute_internal(
           ^^^^^^^^^^^^^^^^^^^^^^^
  File "/Users/lambo/turing/work/4mod/projects/capstone/capstone_py/stream_cycle/venv/lib/python3.12/site-packages/sqlalchemy/orm/session.py", line 2191, in _execute_internal
    result: Result[Any] = compile_state_cls.orm_execute_statement(
                          ^^^^^^^^^^^^^^^^^^^^^^^^^^^^^^^^^^^^^^^^
  File "/Users/lambo/turing/work/4mod/projects/capstone/capstone_py/stream_cycle/venv/lib/python3.12/site-packages/sqlalchemy/orm/context.py", line 293, in orm_execute_statement
    result = conn.execute(
             ^^^^^^^^^^^^^
  File "/Users/lambo/turing/work/4mod/projects/capstone/capstone_py/stream_cycle/venv/lib/python3.12/site-packages/sqlalchemy/engine/base.py", line 1422, in execute
    return meth(
           ^^^^^
  File "/Users/lambo/turing/work/4mod/projects/capstone/capstone_py/stream_cycle/venv/lib/python3.12/site-packages/sqlalchemy/sql/elements.py", line 514, in _execute_on_connection
    return connection._execute_clauseelement(
           ^^^^^^^^^^^^^^^^^^^^^^^^^^^^^^^^^^
  File "/Users/lambo/turing/work/4mod/projects/capstone/capstone_py/stream_cycle/venv/lib/python3.12/site-packages/sqlalchemy/engine/base.py", line 1644, in _execute_clauseelement
    ret = self._execute_context(
          ^^^^^^^^^^^^^^^^^^^^^^
  File "/Users/lambo/turing/work/4mod/projects/capstone/capstone_py/stream_cycle/venv/lib/python3.12/site-packages/sqlalchemy/engine/base.py", line 1850, in _execute_context
    return self._exec_single_context(
           ^^^^^^^^^^^^^^^^^^^^^^^^^^
  File "/Users/lambo/turing/work/4mod/projects/capstone/capstone_py/stream_cycle/venv/lib/python3.12/site-packages/sqlalchemy/engine/base.py", line 1990, in _exec_single_context
    self._handle_dbapi_exception(
  File "/Users/lambo/turing/work/4mod/projects/capstone/capstone_py/stream_cycle/venv/lib/python3.12/site-packages/sqlalchemy/engine/base.py", line 2357, in _handle_dbapi_exception
    raise sqlalchemy_exception.with_traceback(exc_info[2]) from e
  File "/Users/lambo/turing/work/4mod/projects/capstone/capstone_py/stream_cycle/venv/lib/python3.12/site-packages/sqlalchemy/engine/base.py", line 1971, in _exec_single_context
    self.dialect.do_execute(
  File "/Users/lambo/turing/work/4mod/projects/capstone/capstone_py/stream_cycle/venv/lib/python3.12/site-packages/sqlalchemy/engine/default.py", line 919, in do_execute
    cursor.execute(statement, parameters)
sqlalchemy.exc.ProgrammingError: (psycopg2.errors.UndefinedTable) relation "users" does not exist
LINE 2: FROM users 
             ^

[SQL: SELECT users.id AS users_id, users.email AS users_email, users.first_name AS users_first_name, users.last_name AS users_last_name, users.created_at AS users_created_at, users.updated_at AS users_updated_at 
FROM users 
WHERE users.id = %(pk_1)s]
[parameters: {'pk_1': 10}]
(Background on this error at: https://sqlalche.me/e/20/f405)
